Workbook

Sheet Start Here
A1: Fantasy & High-Fantasy Comparative Archetype Atlas — Version 4.0
A2: Normalized-concept visual layer with 1568 citation-backed character evidence records, 1252 character-only evidence relationships, and 281 scoped source passes; focused independent review is recorded for 90 sources and remains pending for 191.
A3: A normalized-concept atlas: being/entity and role/vocation concepts are visual marks; characters and source-native terms are cited evidence
A5: Edition | B5: 4.0 | D5: Key Metric | E5: Value | G5: How to read the atlas
A6: Source fingerprint | B6: sha256:56b3c048fdce9c10348aaa9ed9abe7fefd683df2f7f8db9d9511b7ebf960a1be | D6: Normalized archetypes | E6: =COUNTA('Master Taxonomy'!$A$2:$A$1656) | G6: 1 | H6: Find a source-specific term in Seed Catalogue.
A7: Framework model | B7: Source records + normalized crosswalks | D7: Source corpus records | E7: =COUNTA('Source Corpus'!$A$2:$A$282) | G7: 2 | H7: Follow its Primary and Additional Archetype IDs into Master Taxonomy.
A8: Primary use | B8: Comparative literary/media analysis | D8: Source-specific seed entries | E8: =COUNTA('Seed Catalogue'!$A$2:$A$452) | G8: 3 | H8: Compare only along named axes: ontology, role, power, institution, mechanics, or narrative function.
A9: Secondary use | B9: Encyclopedia/database and reusable archetype discovery | D9: Top-level domains | E9: =COUNTIF('Master Taxonomy'!$M$2:$M$1656,"Domain Root") | G9: 4 | H9: Use Relationship Rules instead of assuming that identical labels are equivalent.
A10: Version policy | B10: Continuity- and edition-specific where material differences exist | G10: 5 | H10: Check Evidence Level, Canon Status, continuity, and Reference URL before making source claims.
G11: 6 | H11: Use Source Priority and Research Queue to extend the corpus without changing the core schema.
G12: 7 | H12: Use Term Metadata for language/witness controls and Adaptation Crosswalk to study how concepts change across media.
A13: Completeness contract
A14: Structural completeness | B14: The schema can represent peoples, beings, roles, powers, institutions, transformations, civilizations, narrative patterns, game mechanics, artifacts, cosmologies, sacred geography, metaphysical laws, rituals, and exchanges without forcing them into race/class bins.
A15: Taxonomic completeness | B15: The normalized hierarchy covers the major reusable archetype families encountered across fantasy traditions and media, with explicit room for culture-specific subfamilies.
A16: Corpus completeness | B16: The source list is intentionally expandable. No finite edition can literally include every fantasy work, edition, adaptation, folk tradition, or live-service update.
A17: Claim discipline | B17: A catalogue entry is not considered fully source-verified until its Evidence Level and Source Reference support the specific continuity claim.
A18: Non-equivalence rule | B18: A normalized family provides a comparison coordinate; it never erases the source concept's distinct metaphysics, history, or cultural meaning.
A20: Eleven analytical domains
A21: People & Beings | B21: Species, peoples, spirits, gods, undead, constructs, monsters, hybrids, and mutable beings. | G21: Roles & Vocations | H21: Martial, rogue, magical, sacred, social, technical, hybrid, and progression roles.
A22: Power Traditions | B22: Sources, domains, methods, costs, techniques, and theories of supernatural power. | G22: States & Transformations | H22: Undeath, curse, possession, mutation, ascension, bond, displacement, and other acquired states.
A23: Institutions & Affiliations | B23: Guilds, orders, schools, sects, parties, factions, castes, states, and social structures. | G23: Narrative Archetypes | H23: Character, antagonist, party, quest, plot, and thematic story functions.
A24: Civilization & Culture Archetypes | B24: States, settlements, ecologies, economies, social organizations, and historical patterns. | G24: Game-Mechanical Archetypes | H24: Combat roles, resources, class structures, progression systems, and unit functions.
A25: Cross-axis rule | B25: One source concept may occupy several domains simultaneously. A witcher, for example, is a transformed human, professional monster hunter, order member, alchemical user, and game build. | G25: Hierarchy rule | H25: Broad families support retrieval; lower tiers preserve distinctions. Parent-child placement is analytical, not a claim of fictional genealogy.
A26: Terminology rule | B26: Preserve source-native terms, translations, and edition labels. Use 'people/being type' as the umbrella rather than treating every distinction as race. | G26: Adaptation rule | H26: Separate adaptations when ontology, powers, institutions, available classes, or world history materially diverge.
A27: Cultural caution | B27: Religious, folkloric, and living traditions require culture-specific scholarship. Similarity is not proof of direct influence or equivalence. | G27: Moral caution | H27: Record source-stated alignments and stereotypes without naturalizing morality as biological fact.
A28: Database rule | B28: Stable IDs remain fixed; deprecated concepts are merged by status rather than deleted or silently reused. | G28: Citation rule | H28: URLs are stored for orientation; deep passes should add edition, chapter, page, episode, codex, or rules-section references.
A30: Relationship ladder: strongest claim to weakest claim
A31: Canonical alias | B31: Same concept in the same continuity. | D31: Exact equivalent | E31: Same across all material dimensions; exceptionally rare. | G31: Close analogue | H31: Strong similarity with source-specific differences. | J31: Partial analogue | K31: Similarity on selected axes only.
A32: Functional analogue | B32: Same social or narrative job. | D32: Mechanical analogue | E32: Same game role or progression function. | G32: Visual analogue | H32: Similar appearance only. | J32: Inspired-by | K32: Requires influence evidence.
A33: Subtype-of | B33: Narrower taxonomic category. | D33: Member-of | E33: Institutional or social membership. | G33: Hybrid-of | H33: Combines multiple normalized families. | J33: Transformed-into | K33: Temporal ontological change.
A34: Adaptation-of | B34: Cross-media or continuity transformation. | D34: Version-of | E34: Edition or incarnation relationship. | G34: Inversion | H34: Deliberate reversal or critique. | J34: Frequently confused-with | K34: Quality-control warning.
A35: Uncertain / disputed | B35: Use when canon, scholarship, translation, or influence remains unresolved.
A37: Recommended research workflow
A38: 1. Define continuity | B38: Choose the exact book corpus, edition, game build, adaptation, or mythic source layer.
A39: 2. Record native type | B39: Ask what the source says the concept is: people, spirit, office, order, profession, class, condition, or mechanic.
A40: 3. Decompose axes | B40: Separate ontology, culture, role, power source, institution, mechanics, and narrative function.
A41: 4. Crosswalk conservatively | B41: Assign a primary archetype and additional axes; document the key distinction.
A42: 5. Cite and version | B42: Add the most precise available source reference and date/version for changing material.
A43: 6. Compare with typed links | B43: State why two entries are analogous rather than merely placing them under one vague label.
A45: Version 2.0 domain expansion
...

Sheet V3 Viz Archive
B2: Version 3 Interactive Relationship Atlas
B3: Deliverable | C3: TypeScript + Sigma.js + Graphology WebGL explorer generated from this workbook.
B4: Run locally | C4: From the project directory: npm install, then npm run dev. Open the local URL printed by Vite.
B5: Build | C5: npm run build regenerates this workbook's JSON graph projection, type-checks the app, and creates dist/.
B7: Semantic zoom | C7: Far: eleven domains and all sources. Middle: archetype families and source bridges. Near: source concepts, canonical entries, adaptations, evidence, and citations.
B8: Coverage view | C8: Separates orientation coverage (281/281 sources) from canonical source-pass coverage (currently 21/281 sources).
B9: Integrity rule | C9: Source Concept Map rows are orientation coordinates derived from editorial corpus notes. They must not be cited as canonical claims. Seed Catalogue remains the canonical source-entry layer.
B11: Graph node types | C11: Domain · normalized archetype · source/tradition · orientation concept · canonical source entry · adaptation crosswalk.
B12: Graph edge types | C12: taxonomy · canonical mapping · orientation mapping · source containment · adaptation · version · influence · implementation.
B14: Version 3 counts | C14: 281 sources · 1655 archetypes · 451 canonical entries · 1465 orientation concepts · 54 source relationships.

Sheet Master Taxonomy
A1: Archetype_ID | B1: Preferred_Name | C1: Domain | D1: Parent_ID | E1: Parent_Name | F1: Tier | G1: Core_Definition | H1: Key_Distinctions | I1: Common_Variants | J1: Typical_Functions | K1: Representative_Terms | L1: Cross_Cultural_Caution | M1: Framework_Status
A2: PPL-000 | B2: People & Beings | C2: People & Beings | E2: =IF(D2="","",IFERROR(VLOOKUP(D2,$A$2:$B$1656,2,FALSE),"")) | F2: 1 | G2: Biological peoples, metaphysical kinds, monsters, spirits, constructs, and other sentient or narratively significant beings. | H2: A top-level analytical domain. Entries may link across domains but should not be collapsed into one another. | J2: Provides the first classification axis for the database. | K2: People & Beings | L2: Preserve each source's ontology, culture, history, and terminology when making comparisons. | M2: Domain Root
A3: ROL-000 | B3: Roles & Vocations | C3: Roles & Vocations | E3: =IF(D3="","",IFERROR(VLOOKUP(D3,$A$2:$B$1656,2,FALSE),"")) | F3: 1 | G3: Professions, combat roles, social offices, religious vocations, magical callings, and formal game classes. | H3: A top-level analytical domain. Entries may link across domains but should not be collapsed into one another. | J3: Provides the first classification axis for the database. | K3: Roles & Vocations | L3: Preserve each source's ontology, culture, history, and terminology when making comparisons. | M3: Domain Root
A4: PWR-000 | B4: Power Traditions | C4: Power Traditions | E4: =IF(D4="","",IFERROR(VLOOKUP(D4,$A$2:$B$1656,2,FALSE),"")) | F4: 1 | G4: Repeatable sources, methods, and logics through which extraordinary power is acquired or exercised. | H4: A top-level analytical domain. Entries may link across domains but should not be collapsed into one another. | J4: Provides the first classification axis for the database. | K4: Power Traditions | L4: Preserve each source's ontology, culture, history, and terminology when making comparisons. | M4: Domain Root
A5: STA-000 | B5: States & Transformations | C5: States & Transformations | E5: =IF(D5="","",IFERROR(VLOOKUP(D5,$A$2:$B$1656,2,FALSE),"")) | F5: 1 | G5: Acquired conditions, templates, curses, awakenings, and changes of body, soul, identity, or status. | H5: A top-level analytical domain. Entries may link across domains but should not be collapsed into one another. | J5: Provides the first classification axis for the database. | K5: States & Transformations | L5: Preserve each source's ontology, culture, history, and terminology when making comparisons. | M5: Domain Root
A6: INS-000 | B6: Institutions & Affiliations | C6: Institutions & Affiliations | E6: =IF(D6="","",IFERROR(VLOOKUP(D6,$A$2:$B$1656,2,FALSE),"")) | F6: 1 | G6: Orders, schools, guilds, sects, castes, houses, armies, and other organized identities. | H6: A top-level analytical domain. Entries may link across domains but should not be collapsed into one another. | J6: Provides the first classification axis for the database. | K6: Institutions & Affiliations | L6: Preserve each source's ontology, culture, history, and terminology when making comparisons. | M6: Domain Root
A7: NAR-000 | B7: Narrative Archetypes | C7: Narrative Archetypes | E7: =IF(D7="","",IFERROR(VLOOKUP(D7,$A$2:$B$1656,2,FALSE),"")) | F7: 1 | G7: Recurring character, party, antagonist, and plot functions used across fantasy media. | H7: A top-level analytical domain. Entries may link across domains but should not be collapsed into one another. | J7: Provides the first classification axis for the database. | K7: Narrative Archetypes | L7: Preserve each source's ontology, culture, history, and terminology when making comparisons. | M7: Domain Root
A8: CIV-000 | B8: Civilization & Culture Archetypes | C8: Civilization & Culture Archetypes | E8: =IF(D8="","",IFERROR(VLOOKUP(D8,$A$2:$B$1656,2,FALSE),"")) | F8: 1 | G8: Reusable patterns for societies, polities, economies, and cultural organization. | H8: A top-level analytical domain. Entries may link across domains but should not be collapsed into one another. | J8: Provides the first classification axis for the database. | K8: Civilization & Culture Archetypes | L8: Preserve each source's ontology, culture, history, and terminology when making comparisons. | M8: Domain Root
A9: MEC-000 | B9: Game-Mechanical Archetypes | C9: Game-Mechanical Archetypes | E9: =IF(D9="","",IFERROR(VLOOKUP(D9,$A$2:$B$1656,2,FALSE),"")) | F9: 1 | G9: Roles and resource patterns defined primarily by rules, encounter design, or player progression. | H9: A top-level analytical domain. Entries may link across domains but should not be collapsed into one another. | J9: Provides the first classification axis for the database. | K9: Game-Mechanical Archetypes | L9: Preserve each source's ontology, culture, history, and terminology when making comparisons. | M9: Domain Root
A10: PPL-100 | B10: Mortal and Natural Peoples | C10: People & Beings | D10: PPL-000 | E10: =IF(D10="","",IFERROR(VLOOKUP(D10,$A$2:$B$1656,2,FALSE),"")) | F10: 2 | G10: Peoples presented as ordinary inhabitants of the setting's natural world, even when their biology differs from humans. | H10: Classify by ontology first; morphology, culture, and game creature type are separate axes. | J10: Organizes source-specific peoples and creatures by the kind of being they are. | K10: Player ancestries; nations; ethnicized fantasy peoples | L10: Preserve each source's ontology, culture, history, and terminology when making comparisons. | M10: Category
A11: PPL-200 | B11: Fae, Nature, and Liminal Beings | C11: People & Beings | D11: PPL-000 | E11: =IF(D11="","",IFERROR(VLOOKUP(D11,$A$2:$B$1656,2,FALSE),"")) | F11: 2 | G11: Beings tied to wilderness, place, season, threshold, enchantment, or an otherworld adjacent to mortal reality. | H11: Classify by ontology first; morphology, culture, and game creature type are separate axes. | J11: Organizes source-specific peoples and creatures by the kind of being they are. | K11: Fae courts; land spirits; trickster beings | L11: Preserve each source's ontology, culture, history, and terminology when making comparisons. | M11: Category
A12: PPL-300 | B12: Spirits and Elementals | C12: People & Beings | D12: PPL-000 | E12: =IF(D12="","",IFERROR(VLOOKUP(D12,$A$2:$B$1656,2,FALSE),"")) | F12: 2 | G12: Incorporeal or semi-corporeal beings constituted by soul, element, concept, memory, dream, or place. | H12: Classify by ontology first; morphology, culture, and game creature type are separate axes. | J12: Organizes source-specific peoples and creatures by the kind of being they are. | K12: Elementals; ancestors; guardian spirits | L12: Preserve each source's ontology, culture, history, and terminology when making comparisons. | M12: Category
A13: PPL-400 | B13: Divine and Celestial Beings | C13: People & Beings | D13: PPL-000 | E13: =IF(D13="","",IFERROR(VLOOKUP(D13,$A$2:$B$1656,2,FALSE),"")) | F13: 2 | G13: Gods, divine emanations, celestial servants, ascended mortals, and beings aligned with sacred cosmic order. | H13: Classify by ontology first; morphology, culture, and game creature type are separate axes. | J13: Organizes source-specific peoples and creatures by the kind of being they are. | K13: Gods; angels; saints; avatars | L13: Preserve each source's ontology, culture, history, and terminology when making comparisons. | M13: Category
A14: PPL-500 | B14: Infernal and Corruptive Beings | C14: People & Beings | D14: PPL-000 | E14: =IF(D14="","",IFERROR(VLOOKUP(D14,$A$2:$B$1656,2,FALSE),"")) | F14: 2 | G14: Demons, devils, fallen celestials, chaos-spawn, and entities whose existence centers on corruption, domination, temptation, or metaphysical disorder. | H14: Classify by ontology first; morphology, culture, and game creature type are separate axes. | J14: Organizes source-specific peoples and creatures by the kind of being they are. | K14: Fiends; demon lords; possessors | L14: Preserve each source's ontology, culture, history, and terminology when making comparisons. | M14: Category
A15: PPL-600 | B15: Undead Beings | C15: People & Beings | D15: PPL-000 | E15: =IF(D15="","",IFERROR(VLOOKUP(D15,$A$2:$B$1656,2,FALSE),"")) | F15: 2 | G15: Beings that persist after biological death through animation, trapped soul, curse, hunger, ritual, or necromantic structure. | H15: Classify by ontology first; morphology, culture, and game creature type are separate axes. | J15: Organizes source-specific peoples and creatures by the kind of being they are. | K15: Ghosts; vampires; liches; revenants | L15: Preserve each source's ontology, culture, history, and terminology when making comparisons. | M15: Category
A16: PPL-700 | B16: Constructs and Artificial Life | C16: People & Beings | D16: PPL-000 | E16: =IF(D16="","",IFERROR(VLOOKUP(D16,$A$2:$B$1656,2,FALSE),"")) | F16: 2 | G16: Created beings whose bodies or minds are deliberately manufactured, assembled, grown, enchanted, or replicated. | H16: Classify by ontology first; morphology, culture, and game creature type are separate axes. | J16: Organizes source-specific peoples and creatures by the kind of being they are. | K16: Golems; homunculi; clockwork people | L16: Preserve each source's ontology, culture, history, and terminology when making comparisons. | M16: Category
A17: PPL-800 | B17: Dragons and Legendary Beasts | C17: People & Beings | D17: PPL-000 | E17: =IF(D17="","",IFERROR(VLOOKUP(D17,$A$2:$B$1656,2,FALSE),"")) | F17: 2 | G17: Iconic nonhuman beasts whose intelligence, scale, magical potency, or symbolic role exceeds ordinary fauna. | H17: Classify by ontology first; morphology, culture, and game creature type are separate axes. | J17: Organizes source-specific peoples and creatures by the kind of being they are. | K17: Dragons; griffins; hydras; world beasts | L17: Preserve each source's ontology, culture, history, and terminology when making comparisons. | M17: Category
A18: PPL-900 | B18: Plant, Fungal, Ooze, and Collective Life | C18: People & Beings | D18: PPL-000 | E18: =IF(D18="","",IFERROR(VLOOKUP(D18,$A$2:$B$1656,2,FALSE),"")) | F18: 2 | G18: Beings based on non-animal life, amorphous bodies, swarms, colonies, or distributed consciousness. | H18: Classify by ontology first; morphology, culture, and game creature type are separate axes. | J18: Organizes source-specific peoples and creatures by the kind of being they are. | K18: Plantfolk; slimes; hive minds | L18: Preserve each source's ontology, culture, history, and terminology when making comparisons. | M18: Category
A19: PPL-1000 | B19: Shapeshifters, Hybrids, and Mutable Peoples | C19: People & Beings | D19: PPL-000 | E19: =IF(D19="","",IFERROR(VLOOKUP(D19,$A$2:$B$1656,2,FALSE),"")) | F19: 2 | G19: Beings defined by mixed ancestry, mutable form, copied identity, animal transformation, possession, or body exchange. | H19: Classify by ontology first; morphology, culture, and game creature type are separate axes. | J19: Organizes source-specific peoples and creatures by the kind of being they are. | K19: Therianthropes; doppelgangers; chimeras | L19: Preserve each source's ontology, culture, history, and terminology when making comparisons. | M19: Category
A20: PPL-1100 | B20: Cosmic, Aberrant, and Otherworldly Beings | C20: People & Beings | D20: PPL-000 | E20: =IF(D20="","",IFERROR(VLOOKUP(D20,$A$2:$B$1656,2,FALSE),"")) | F20: 2 | G20: Entities whose bodies, minds, origins, or causal rules lie outside the setting's normal natural and supernatural orders. | H20: Classify by ontology first; morphology, culture, and game creature type are separate axes. | J20: Organizes source-specific peoples and creatures by the kind of being they are. | K20: Aberrations; void beings; reality parasites | L20: Preserve each source's ontology, culture, history, and terminology when making comparisons. | M20: Category
A21: PPL-101 | B21: Human and Near-Human Peoples | C21: People & Beings | D21: PPL-100 | E21: =IF(D21="","",IFERROR(VLOOKUP(D21,$A$2:$B$1656,2,FALSE),"")) | F21: 3 | G21: Humans or humanlike peoples whose differences are primarily cultural, historical, adaptive, or mildly supernatural rather than a separate metaphysical kind. | H21: Source-specific examples may differ biologically, metaphysically, culturally, and morally; map them as analogues unless equivalence is explicit. | I21: human; mortal; man; tall-man; near-human | J21: Playable ancestry, neighboring civilization, minority people, enemy people, or cultural foil. | K21: human; mortal; man; tall-man; near-human | L21: Preserve each source's ontology, culture, history, and terminology when making comparisons. | M21: Core Family
A22: PPL-102 | B22: Elf-Derived Peoples | C22: People & Beings | D22: PPL-100 | E22: =IF(D22="","",IFERROR(VLOOKUP(D22,$A$2:$B$1656,2,FALSE),"")) | F22: 3 | G22: Graceful or otherworldly humanoids commonly associated with longevity, heightened perception, magic, nature, memory, or a fading elder civilization. | H22: Source-specific examples may differ biologically, metaphysically, culturally, and morally; map them as analogues unless equivalence is explicit. | I22: elf; elven; elvish; elder folk; faerie-blooded | J22: Playable ancestry, neighboring civilization, minority people, enemy people, or cultural foil. | K22: elf; elven; elvish; elder folk; faerie-blooded | L22: Do not treat Tolkien's Quendi, folkloric elves, game ancestries, and modern anime elves as one ontology. | M22: Core Family
A23: PPL-103 | B23: Dwarf-Derived Peoples | C23: People & Beings | D23: PPL-100 | E23: =IF(D23="","",IFERROR(VLOOKUP(D23,$A$2:$B$1656,2,FALSE),"")) | F23: 3 | G23: Compact, hardy humanoids often linked with stone, mining, smithcraft, clan memory, subterranean halls, or martial resilience. | H23: Source-specific examples may differ biologically, metaphysically, culturally, and morally; map them as analogues unless equivalence is explicit. | I23: dwarf; dwarven; dwarf-kind; mountain folk | J23: Playable ancestry, neighboring civilization, minority people, enemy people, or cultural foil. | K23: dwarf; dwarven; dwarf-kind; mountain folk | L23: Preserve each source's ontology, culture, history, and terminology when making comparisons. | M23: Core Family
A24: PPL-104 | B24: Halfling and Smallfolk Peoples | C24: People & Beings | D24: PPL-100 | E24: =IF(D24="","",IFERROR(VLOOKUP(D24,$A$2:$B$1656,2,FALSE),"")) | F24: 3 | G24: Small-statured humanoids whose archetype emphasizes domesticity, stealth, luck, community, mobility, or being overlooked by larger powers. | H24: Source-specific examples may differ biologically, metaphysically, culturally, and morally; map them as analogues unless equivalence is explicit. | I24: halfling; hobbit-like; kender-like; smallfolk | J24: Playable ancestry, neighboring civilization, minority people, enemy people, or cultural foil. | K24: halfling; hobbit-like; kender-like; smallfolk | L24: Preserve each source's ontology, culture, history, and terminology when making comparisons. | M24: Core Family
A25: PPL-105 | B25: Gnome and Tinkerfolk Peoples | C25: People & Beings | D25: PPL-100 | E25: =IF(D25="","",IFERROR(VLOOKUP(D25,$A$2:$B$1656,2,FALSE),"")) | F25: 3 | G25: Small humanoids associated with craft, curiosity, illusion, engineering, alchemy, scholarship, or hidden communities. | H25: Source-specific examples may differ biologically, metaphysically, culturally, and morally; map them as analogues unless equivalence is explicit. | I25: gnome; tinkerfolk; deep gnome; garden-gnome analogue | J25: Playable ancestry, neighboring civilization, minority people, enemy people, or cultural foil. | K25: gnome; tinkerfolk; deep gnome; garden-gnome analogue | L25: Preserve each source's ontology, culture, history, and terminology when making comparisons. | M25: Core Family
A26: PPL-106 | B26: Orc-Derived Peoples | C26: People & Beings | D26: PPL-100 | E26: =IF(D26="","",IFERROR(VLOOKUP(D26,$A$2:$B$1656,2,FALSE),"")) | F26: 3 | G26: Powerfully built humanoids often framed through warfare, marginalization, corruption, honor culture, clan identity, or contested personhood. | H26: Source-specific examples may differ biologically, metaphysically, culturally, and morally; map them as analogues unless equivalence is explicit. | I26: orc; orcish; ork; half-orc | J26: Playable ancestry, neighboring civilization, minority people, enemy people, or cultural foil. | K26: orc; orcish; ork; half-orc | L26: Track whether 'orc' denotes a created enemy species, an ethnicized people, a playable ancestry, or a reclaimed identity. | M26: Core Family
A27: PPL-107 | B27: Goblinoid Peoples | C27: People & Beings | D27: PPL-100 | E27: =IF(D27="","",IFERROR(VLOOKUP(D27,$A$2:$B$1656,2,FALSE),"")) | F27: 3 | G27: Small or medium humanoids associated with subterranean life, scavenging, ambush, craft, trickery, militarized hierarchy, or outsider societies. | H27: Source-specific examples may differ biologically, metaphysically, culturally, and morally; map them as analogues unless equivalence is explicit. | I27: goblin; hobgoblin; bugbear; gremlin-like | J27: Playable ancestry, neighboring civilization, minority people, enemy people, or cultural foil. | K27: goblin; hobgoblin; bugbear; gremlin-like | L27: Preserve each source's ontology, culture, history, and terminology when making comparisons. | M27: Core Family
A28: PPL-108 | B28: Giantkin Peoples | C28: People & Beings | D28: PPL-100 | E28: =IF(D28="","",IFERROR(VLOOKUP(D28,$A$2:$B$1656,2,FALSE),"")) | F28: 3 | G28: Humanoid peoples of exceptional scale, often linked with primordial ancestry, mountains, elemental forces, divine lineage, or fading ages. | H28: Source-specific examples may differ biologically, metaphysically, culturally, and morally; map them as analogues unless equivalence is explicit. | I28: giant; jotunn-like; titan-blooded; goliath | J28: Playable ancestry, neighboring civilization, minority people, enemy people, or cultural foil. | K28: giant; jotunn-like; titan-blooded; goliath | L28: Preserve each source's ontology, culture, history, and terminology when making comparisons. | M28: Core Family
A29: PPL-109 | B29: Ogrekin Peoples | C29: People & Beings | D29: PPL-100 | E29: =IF(D29="","",IFERROR(VLOOKUP(D29,$A$2:$B$1656,2,FALSE),"")) | F29: 3 | G29: Large humanoids commonly framed as physically powerful, socially marginal, cannibalistic, mercenary, clan-based, or unexpectedly sophisticated. | H29: Source-specific examples may differ biologically, metaphysically, culturally, and morally; map them as analogues unless equivalence is explicit. | I29: ogre; ogrekin; oni-like giant humanoid | J29: Playable ancestry, neighboring civilization, minority people, enemy people, or cultural foil. | K29: ogre; ogrekin; oni-like giant humanoid | L29: Preserve each source's ontology, culture, history, and terminology when making comparisons. | M29: Core Family
A30: PPL-110 | B30: Trollkin Peoples | C30: People & Beings | D30: PPL-100 | E30: =IF(D30="","",IFERROR(VLOOKUP(D30,$A$2:$B$1656,2,FALSE),"")) | F30: 3 | G30: Regenerative, stone-associated, monstrous, folkloric, or tribal humanoids whose meanings range from person to predator. | H30: Source-specific examples may differ biologically, metaphysically, culturally, and morally; map them as analogues unless equivalence is explicit. | I30: troll; trollkin; troll-blooded | J30: Playable ancestry, neighboring civilization, minority people, enemy people, or cultural foil. | K30: troll; trollkin; troll-blooded | L30: Separate Scandinavian folkloric trolls, Tolkienian trolls, and game troll peoples. | M30: Core Family
A31: PPL-111 | B31: Cyclopean Peoples | C31: People & Beings | D31: PPL-100 | E31: =IF(D31="","",IFERROR(VLOOKUP(D31,$A$2:$B$1656,2,FALSE),"")) | F31: 3 | G31: One-eyed or otherwise singular-sensed giant humanoids, often connected with smithing, prophecy, isolation, or brute force. | H31: Source-specific examples may differ biologically, metaphysically, culturally, and morally; map them as analogues unless equivalence is explicit. | I31: cyclops; one-eyed giant | J31: Playable ancestry, neighboring civilization, minority people, enemy people, or cultural foil. | K31: cyclops; one-eyed giant | L31: Preserve each source's ontology, culture, history, and terminology when making comparisons. | M31: Core Family
A32: PPL-112 | B32: Lizardfolk and Reptilian Peoples | C32: People & Beings | D32: PPL-100 | E32: =IF(D32="","",IFERROR(VLOOKUP(D32,$A$2:$B$1656,2,FALSE),"")) | F32: 3 | G32: Humanoid reptiles whose settings may emphasize alien cognition, ancient civilizations, survival ecology, or draconic ancestry. | H32: Source-specific examples may differ biologically, metaphysically, culturally, and morally; map them as analogues unless equivalence is explicit. | I32: lizardfolk; saurian; argonian-like; reptilian | J32: Playable ancestry, neighboring civilization, minority people, enemy people, or cultural foil. | K32: lizardfolk; saurian; argonian-like; reptilian | L32: Preserve each source's ontology, culture, history, and terminology when making comparisons. | M32: Core Family
... A177: PPL-1112 | B177: Incomprehensible Collective Intelligences | C177: People & Beings | D177: PPL-1100 | E177: =IF(D177="","",IFERROR(VLOOKUP(D177,$A$2:$B$1656,2,FALSE),"")) | F177: 3 | G177: Vast minds distributed across species, dimensions, stars, or informational systems beyond individual-scale personhood. | H177: Source-specific examples may differ biologically, metaphysically, culturally, and morally; map them as analogues unless equivalence is explicit. | I177: cosmic hive mind; overmind | J177: Cosmic threat, reality challenge, alien civilization, metaphysical mystery, or boundary of comprehension. | K177: cosmic hive mind; overmind | L177: Preserve each source's ontology, culture, history, and terminology when making comparisons. | M177: Core Family
A178: ROL-100 | B178: Martial Roles | C178: Roles & Vocations | D178: ROL-000 | E178: =IF(D178="","",IFERROR(VLOOKUP(D178,$A$2:$B$1656,2,FALSE),"")) | F178: 2 | G178: Combatants whose primary expertise is weapons, armor, physical discipline, command, or battlefield endurance. | H178: A role may be a profession, class, office, order, build, or narrative identity; record the native type separately. | J178: Groups source-specific classes and vocations by practical and symbolic function. | K178: Martial Roles | L178: Preserve each source's ontology, culture, history, and terminology when making comparisons. | M178: Category
A179: ROL-200 | B179: Rogue and Underworld Roles | C179: Roles & Vocations | D179: ROL-000 | E179: =IF(D179="","",IFERROR(VLOOKUP(D179,$A$2:$B$1656,2,FALSE),"")) | F179: 2 | G179: Stealth, infiltration, theft, assassination, deception, sabotage, and informal survival professions. | H179: A role may be a profession, class, office, order, build, or narrative identity; record the native type separately. | J179: Groups source-specific classes and vocations by practical and symbolic function. | K179: Rogue and Underworld Roles | L179: Preserve each source's ontology, culture, history, and terminology when making comparisons. | M179: Category
A180: ROL-300 | B180: Arcane and Scholarly Magic Roles | C180: Roles & Vocations | D180: ROL-000 | E180: =IF(D180="","",IFERROR(VLOOKUP(D180,$A$2:$B$1656,2,FALSE),"")) | F180: 2 | G180: Practitioners whose extraordinary abilities are framed as learned, innate, technical, symbolic, or occult magic. | H180: A role may be a profession, class, office, order, build, or narrative identity; record the native type separately. | J180: Groups source-specific classes and vocations by practical and symbolic function. | K180: Arcane and Scholarly Magic Roles | L180: Preserve each source's ontology, culture, history, and terminology when making comparisons. | M180: Category
A181: ROL-400 | B181: Divine and Religious Roles | C181: Roles & Vocations | D181: ROL-000 | E181: =IF(D181="","",IFERROR(VLOOKUP(D181,$A$2:$B$1656,2,FALSE),"")) | F181: 2 | G181: Vocations grounded in worship, sacred authority, miracles, prophecy, ritual office, or opposition to spiritual threats. | H181: A role may be a profession, class, office, order, build, or narrative identity; record the native type separately. | J181: Groups source-specific classes and vocations by practical and symbolic function. | K181: Divine and Religious Roles | L181: Preserve each source's ontology, culture, history, and terminology when making comparisons. | M181: Category
A182: ROL-500 | B182: Nature and Spirit Roles | C182: Roles & Vocations | D182: ROL-000 | E182: =IF(D182="","",IFERROR(VLOOKUP(D182,$A$2:$B$1656,2,FALSE),"")) | F182: 2 | G182: Vocations that mediate wilderness, animals, elements, ancestors, land spirits, or ecological reciprocity. | H182: A role may be a profession, class, office, order, build, or narrative identity; record the native type separately. | J182: Groups source-specific classes and vocations by practical and symbolic function. | K182: Nature and Spirit Roles | L182: Preserve each source's ontology, culture, history, and terminology when making comparisons. | M182: Category
A183: ROL-600 | B183: Healing, Craft, and Knowledge Roles | C183: Roles & Vocations | D183: ROL-000 | E183: =IF(D183="","",IFERROR(VLOOKUP(D183,$A$2:$B$1656,2,FALSE),"")) | F183: 2 | G183: Supportive, productive, scholarly, artistic, and technical professions that sustain people and institutions. | H183: A role may be a profession, class, office, order, build, or narrative identity; record the native type separately. | J183: Groups source-specific classes and vocations by practical and symbolic function. | K183: Healing, Craft, and Knowledge Roles | L183: Preserve each source's ontology, culture, history, and terminology when making comparisons. | M183: Category
A184: ROL-700 | B184: Leadership and Social Office Roles | C184: Roles & Vocations | D184: ROL-000 | E184: =IF(D184="","",IFERROR(VLOOKUP(D184,$A$2:$B$1656,2,FALSE),"")) | F184: 2 | G184: Roles defined by authority, status, governance, diplomacy, lineage, administration, or command. | H184: A role may be a profession, class, office, order, build, or narrative identity; record the native type separately. | J184: Groups source-specific classes and vocations by practical and symbolic function. | K184: Leadership and Social Office Roles | L184: Preserve each source's ontology, culture, history, and terminology when making comparisons. | M184: Category
...

Sheet Source Corpus
A1: Source_ID | B1: Title_or_Franchise | C1: Creator_Studio | D1: Medium | E1: Region_Tradition | F1: First_Appearance | G1: Continuity_Unit | H1: Priority_Tier | I1: Distinctive_Contribution | J1: Scope_Note | K1: Reference_URL | L1: Status
A2: SRC-001 | B2: Ancient Greek Mythology | C2: Multiple oral and literary traditions | D2: Mythology / Folklore | E2: Mediterranean / Greek | F2: Archaic–Classical antiquity | G2: Culture-specific corpus | H2: Tier 1 | I2: Gods, demigods, heroes, monsters, nymphs, underworld journeys, metamorphosis, prophecy. | J2: Treat adaptations/editions separately when taxonomically material. | K2: https://en.wikipedia.org/wiki/Ancient_Greek_Mythology | L2: Included
A3: SRC-002 | B3: Norse Mythology | C3: Old Norse oral and literary traditions | D3: Mythology / Folklore | E3: Northern Europe / Norse | F3: Medieval textual witnesses | G3: Poetic Edda, Prose Edda, sagas | H3: Tier 1 | I3: Jötnar, elves, dwarfs, draugr, world serpent, valkyries, fate, cyclical apocalypse. | J3: Treat adaptations/editions separately when taxonomically material. | K3: https://en.wikipedia.org/wiki/Norse_Mythology | L3: Included
A4: SRC-003 | B4: Irish Mythological Cycle | C4: Irish oral and manuscript traditions | D4: Mythology / Folklore | E4: Ireland | F4: Medieval textual witnesses | G4: Mythological, Ulster, Fenian, and Kings' cycles | H4: Tier 1 | I4: Otherworld peoples, geasa, heroic warbands, sovereignty, transformation, fairy mounds. | J4: Treat adaptations/editions separately when taxonomically material. | K4: https://en.wikipedia.org/wiki/Irish_Mythological_Cycle | L4: Included
A5: SRC-004 | B5: The Mabinogion | C5: Medieval Welsh authors and oral traditions | D5: Literature / Mythic Cycle | E5: Wales | F5: 12th–14th centuries | G5: Welsh tale collection | H5: Tier 1 | I5: Otherworld journeys, enchantment, shapechange, cursed sovereignty, heroic kinship. | J5: Treat adaptations/editions separately when taxonomically material. | K5: https://en.wikipedia.org/wiki/The_Mabinogion | L5: Included
A6: SRC-005 | B6: Arthurian Legend | C6: Multiple medieval and later authors | D6: Literature / Mythic Cycle | E6: Britain / France / Europe | F6: 12th century onward | G6: Romance tradition | H6: Tier 1 | I6: Knights, quests, holy relics, enchanted weapons, courtly orders, grail patterns. | J6: Treat adaptations/editions separately when taxonomically material. | K6: https://en.wikipedia.org/wiki/Arthurian_Legend | L6: Included
A7: SRC-006 | B7: Kalevala | C7: Compiled by Elias Lönnrot from Finnish and Karelian oral poetry | D7: Epic / Folklore | E7: Finland / Karelia | F7: 1835/1849 | G7: National epic compilation | H7: Tier 1 | I7: Song magic, smithing, shamanic heroes, artifact quest, rival cultures. | J7: Treat adaptations/editions separately when taxonomically material. | K7: https://en.wikipedia.org/wiki/Kalevala | L7: Included
A8: SRC-007 | B8: Slavic Folklore | C8: Multiple regional traditions | D8: Mythology / Folklore | E8: Eastern and Central Europe | F8: Premodern and modern collections | G8: Culture-specific corpus | H8: Tier 1 | I8: Vampiric revenants, household spirits, witches, forest beings, dragons, deathless sorcerers. | J8: Treat adaptations/editions separately when taxonomically material. | K8: https://en.wikipedia.org/wiki/Slavic_Folklore | L8: Included
A9: SRC-008 | B9: Grimm Fairy Tales | C9: Jacob and Wilhelm Grimm, collectors/editors | D9: Fairy Tale Collection | E9: German-speaking Europe | F9: 1812 onward | G9: Multiple editions | H9: Tier 1 | I9: Witches, enchanted animals, curses, helpers, trials, transformed royals, household magic. | J9: Treat adaptations/editions separately when taxonomically material. | K9: https://en.wikipedia.org/wiki/Grimm_Fairy_Tales | L9: Included
A10: SRC-009 | B10: One Thousand and One Nights | C10: Multiple Arabic, Persian, South Asian, and later compilers | D10: Frame Tale / Folklore | E10: Middle East / South Asia | F10: Medieval compilation | G10: Multiple manuscript and translation traditions | H10: Tier 1 | I10: Djinn, sorcerers, talismans, magical travel, tricksters, merchants, nested stories. | J10: Treat adaptations/editions separately when taxonomically material. | K10: https://en.wikipedia.org/wiki/One_Thousand_and_One_Nights | L10: Included
A11: SRC-010 | B11: Jinn Traditions | C11: Arabic and Islamic religious, folkloric, and literary traditions | D11: Mythology / Folklore | E11: Middle East / Islamic world | F11: Qur'anic and later traditions | G11: Culture-specific corpus | H11: Tier 1 | I11: Spirit personhood, free will, binding, possession, fire origins, parallel societies. | J11: Treat adaptations/editions separately when taxonomically material. | K11: https://en.wikipedia.org/wiki/Jinn_Traditions | L11: Included
A12: SRC-011 | B12: Shahnameh | C12: Ferdowsi | D12: Epic Literature | E12: Persian / Iranian | F12: c. 1010 | G12: Persian epic | H12: Tier 1 | I12: Heroic warriors, kingship, demons, magical birds, tragic champions, dynastic cycles. | J12: Treat adaptations/editions separately when taxonomically material. | K12: https://en.wikipedia.org/wiki/Shahnameh | L12: Included
... A282: SRC-281 | B282: Age of Mythology: Retold | C282: World's Edge, Forgotten Empires, and Xbox Game Studios | D282: Video Game / Real-Time Strategy | E282: United States / global commercial adaptation | F282: 2024; Version 2.0 snapshot through August 2, 2026 | G282: Retold base game plus dated official pantheon and god-pack expansions | H282: Tier 1 | I282: A major adaptation laboratory that converts deities into faction and technology choices, worship into favor economies, myths into units and counters, divine intervention into activated god powers, relics into map objectives, and cosmic ages into progression tiers. | J282: Commercial game adaptation, not evidence for the source traditions it represents. Version-stamp pantheon rosters, expansions, balance changes, and names; analyze Greek, Egyptian, Norse, Atlantean, Chinese, Japanese, and Mexica/Aztec adaptation layers separately. | K282: https://www.ageofempires.com/games/age-of-mythology-retold/ | L282: Included

Sheet Seed Catalogue
A1: Entry_ID | B1: Canonical_Name | C1: Source_ID | D1: Source_Title | E1: Continuity | F1: Native_Record_Type | G1: Primary_Archetype_ID | H1: Primary_Archetype_Name | I1: Additional_Archetype_IDs | J1: Additional_Archetype_Names | K1: Ontology_or_Role_Summary | L1: Power_Basis | M1: Key_Distinction | N1: Comparative_Notes | O1: Canon_Status | P1: Evidence_Level | Q1: Source_Reference | R1: Reference_URL | S1: Review_Status
A2: ENT-0001 | B2: Quendi (Elves) | C2: SRC-026 | D2: Tolkien's Legendarium | E2: Legendarium (literary corpus) | F2: People / metaphysical kind | G2: PPL-102 | H2: =IFERROR(VLOOKUP(G2,'Master Taxonomy'!$A$2:$B$1656,2,FALSE),"") | K2: The awakened Firstborn Children of Ilúvatar, with multiple historical and cultural divisions. | L2: Created people; embodied immortal life bound to Arda. | M2: Their immortality, fate, and relation to Arda differ fundamentally from most game-elves. | N2: Primary reference point for the modern high-fantasy elf family. | O2: Primary canon | P2: Official reference reviewed | Q2: Tolkien Estate setting overview and primary legendarium corpus. | R2: https://www.tolkienestate.com/writing/ | S2: Seeded
A3: ENT-0002 | B3: Vanyar | C3: SRC-026 | D3: Tolkien's Legendarium | E3: Legendarium (literary corpus) | F3: Elven people | G3: PPL-102 | H3: =IFERROR(VLOOKUP(G3,'Master Taxonomy'!$A$2:$B$1656,2,FALSE),"") | K3: One of the principal Eldarin peoples, associated with Aman and the Valar. | L3: Lineage, migration history, and culture. | M3: A canonical subgroup, not a separate biological species. | N3: High or celestial elf analogues are only partial. | O3: Primary canon | P3: Official reference reviewed | Q3: Tolkien Estate setting overview and primary legendarium corpus. | R3: https://www.tolkienestate.com/writing/ | S3: Seeded
A4: ENT-0003 | B4: Noldor | C4: SRC-026 | D4: Tolkien's Legendarium | E4: Legendarium (literary corpus) | F4: Elven people | G4: PPL-102 | H4: =IFERROR(VLOOKUP(G4,'Master Taxonomy'!$A$2:$B$1656,2,FALSE),"") | I4: ROL-306 | J4: Magical Scholar | K4: An Eldarin people renowned for craft, knowledge, political tragedy, and exile. | L4: Cultural learning, craft, and personal spiritual stature. | M4: Their defining traits are historical and cultural rather than a game-stat package. | N4: Influential on learned, tragic, and high-elven archetypes. | O4: Primary canon | P4: Official reference reviewed | Q4: Tolkien Estate setting overview and primary legendarium corpus. | R4: https://www.tolkienestate.com/writing/ | S4: Seeded
A5: ENT-0004 | B5: Teleri and Sindar | C5: SRC-026 | D5: Tolkien's Legendarium | E5: Legendarium (literary corpus) | F5: Elven peoples | G5: PPL-102 | H5: =IFERROR(VLOOKUP(G5,'Master Taxonomy'!$A$2:$B$1656,2,FALSE),"") | K5: Related Eldarin peoples whose histories include maritime, forest, and Beleriandic cultures. | L5: Kinship, migration, geography, and cultural development. | M5: The umbrella conceals several distinct peoples and political histories. | N5: Partial source for sea-elf and woodland-elf developments. | O5: Primary canon | P5: Official reference reviewed | Q5: Tolkien Estate setting overview and primary legendarium corpus. | R5: https://www.tolkienestate.com/writing/ | S5: Seeded
A6: ENT-0005 | B6: Avari | C6: SRC-026 | D6: Tolkien's Legendarium | E6: Legendarium (literary corpus) | F6: Elven peoples | G6: PPL-102 | H6: =IFERROR(VLOOKUP(G6,'Master Taxonomy'!$A$2:$B$1656,2,FALSE),"") | K6: Elves who refused the Great Journey, comprising multiple unenumerated peoples. | L6: Historical choice and later cultural divergence. | M6: Not synonymous with evil, dark, or subterranean elves. | N6: Useful corrective to moralized elf subrace taxonomies. | O6: Primary canon | P6: Official reference reviewed | Q6: Tolkien Estate setting overview and primary legendarium corpus. | R6: https://www.tolkienestate.com/writing/ | S6: Seeded
A7: ENT-0006 | B7: Khazâd (Dwarves) | C7: SRC-026 | D7: Tolkien's Legendarium | E7: Legendarium (literary corpus) | F7: Created people | G7: PPL-103 | H7: =IFERROR(VLOOKUP(G7,'Master Taxonomy'!$A$2:$B$1656,2,FALSE),"") | K7: A people fashioned by Aulë and adopted into Ilúvatar's design, organized in kindreds and houses. | L7: Created ancestry, craft tradition, kinship, and long memory. | M7: Their origin and eschatology are specific to Tolkien's cosmology. | N7: Central modern template for dwarven peoples. | O7: Primary canon | P7: Official reference reviewed | Q7: Tolkien Estate setting overview and primary legendarium corpus. | R7: https://www.tolkienestate.com/writing/ | S7: Seeded
A8: ENT-0007 | B8: Hobbits | C8: SRC-026 | D8: Tolkien's Legendarium | E8: Legendarium (literary corpus) | F8: Human-related people | G8: PPL-104 | H8: =IFERROR(VLOOKUP(G8,'Master Taxonomy'!$A$2:$B$1656,2,FALSE),"") | K8: A small-statured people associated with agrarian domesticity, resilience, and obscurity. | L8: Natural people with cultural and regional branches. | M8: They are a people and culture, not inherently an adventuring class. | N8: Primary model for halflings and domestic smallfolk. | O8: Primary canon | P8: Official reference reviewed | Q8: Tolkien Estate setting overview and primary legendarium corpus. | R8: https://www.tolkienestate.com/writing/ | S8: Seeded
A9: ENT-0008 | B9: Men (Atani and later peoples) | C9: SRC-026 | D9: Tolkien's Legendarium | E9: Legendarium (literary corpus) | F9: Mortal people | G9: PPL-101 | H9: =IFERROR(VLOOKUP(G9,'Master Taxonomy'!$A$2:$B$1656,2,FALSE),"") | K9: The mortal Secondborn Children of Ilúvatar, divided across many nations and histories. | L9: Natural people; mortality is metaphysically significant. | M9: Human cultures must not be collapsed into one archetypal society. | N9: Baseline human plurality in epic fantasy. | O9: Primary canon | P9: Official reference reviewed | Q9: Tolkien Estate setting overview and primary legendarium corpus. | R9: https://www.tolkienestate.com/writing/ | S9: Seeded
A10: ENT-0009 | B10: Dúnedain | C10: SRC-026 | D10: Tolkien's Legendarium | E10: Legendarium (literary corpus) | F10: Human lineage and culture | G10: PPL-101 | H10: =IFERROR(VLOOKUP(G10,'Master Taxonomy'!$A$2:$B$1656,2,FALSE),"") | I10: ROL-125 | J10: Ranger | K10: Long-lived Númenórean-descended human peoples, including northern and southern branches. | L10: Lineage, inherited longevity, culture, and historical institutions. | M10: Not a separate species; 'ranger' applies especially to a later northern role. | N10: Long-lived lost-kingdom human and ranger analogues. | O10: Primary canon | P10: Official reference reviewed | Q10: Tolkien Estate setting overview and primary legendarium corpus. | R10: https://www.tolkienestate.com/writing/ | S10: Seeded
A11: ENT-0010 | B11: Ents | C11: SRC-026 | D11: Tolkien's Legendarium | E11: Legendarium (literary corpus) | F11: Nonhuman people | G11: PPL-901 | H11: =IFERROR(VLOOKUP(G11,'Master Taxonomy'!$A$2:$B$1656,2,FALSE),"") | I11: PPL-203 | J11: Dryads and Tree-Bound Beings | K11: Ancient tree-shepherds with personhood, language, memory, and ecological vocation. | L11: Created or awakened nature-associated beings. | M11: Not simply animated trees or generic elementals. | N11: Major treefolk and ecological guardian archetype. | O11: Primary canon | P11: Official reference reviewed | Q11: Tolkien Estate setting overview and primary legendarium corpus. | R11: https://www.tolkienestate.com/writing/ | S11: Seeded
A12: ENT-0011 | B12: Ainur | C12: SRC-026 | D12: Tolkien's Legendarium | E12: Legendarium (literary corpus) | F12: Primordial spiritual beings | G12: PPL-400 | H12: =IFERROR(VLOOKUP(G12,'Master Taxonomy'!$A$2:$B$1656,2,FALSE),"") | K12: Pre-cosmic spirits who participate in the shaping and governance of the created world. | L12: Created spiritual nature and delegated cosmic authority. | M12: They are neither a biological race nor a single moral faction. | N12: Comparable to angelic or demiurgic orders only with caution. | O12: Primary canon | P12: Official reference reviewed | Q12: Tolkien Estate setting overview and primary legendarium corpus. | R12: https://www.tolkienestate.com/writing/ | S12: Seeded
A13: ENT-0012 | B13: Valar | C13: SRC-026 | D13: Tolkien's Legendarium | E13: Legendarium (literary corpus) | F13: Divine governing order | G13: PPL-401 | H13: =IFERROR(VLOOKUP(G13,'Master Taxonomy'!$A$2:$B$1656,2,FALSE),"") | I13: PPL-405 | J13: Divine Servitors | K13: The greatest Ainur who enter Arda and exercise delegated guardianship over it. | L13: Spiritual nature and divinely delegated authority. | M13: Often called gods by inhabitants, but subordinate to Ilúvatar. | N13: Functional analogue to pantheons, not exact polytheistic deities. | O13: Primary canon | P13: Official reference reviewed | Q13: Tolkien Estate setting overview and primary legendarium corpus. | R13: https://www.tolkienestate.com/writing/ | S13: Seeded
A14: ENT-0013 | B14: Maiar | C14: SRC-026 | D14: Tolkien's Legendarium | E14: Legendarium (literary corpus) | F14: Lesser Ainur | G14: PPL-404 | H14: =IFERROR(VLOOKUP(G14,'Master Taxonomy'!$A$2:$B$1656,2,FALSE),"") | I14: PPL-405 | J14: Divine Servitors | K14: Ainur of lesser order who serve, teach, rule, tempt, or oppose within Arda. | L14: Spiritual nature; variable embodiment and allegiance. | M14: Includes radically different figures and cannot be treated as one profession. | N14: Angel, spirit-lord, and embodied emissary analogues. | O14: Primary canon | P14: Official reference reviewed | Q14: Tolkien Estate setting overview and primary legendarium corpus. | R14: https://www.tolkienestate.com/writing/ | S14: Seeded
A15: ENT-0014 | B15: Istari (Wizards) | C15: SRC-026 | D15: Tolkien's Legendarium | E15: Legendarium (literary corpus) | F15: Invested emissary order | G15: ROL-301 | H15: =IFERROR(VLOOKUP(G15,'Master Taxonomy'!$A$2:$B$1656,2,FALSE),"") | I15: PPL-405 | J15: Divine Servitors | K15: Maiar sent in constrained embodied form to counsel resistance against Sauron. | L15: Delegated mission, spiritual nature, knowledge, and limited embodied power. | M15: ‘Wizard’ here denotes an order and identity, not merely a learned spellcaster class. | N15: A key example of one source term crossing role, being-type, and institution. | O15: Primary canon | P15: Official reference reviewed | Q15: Tolkien Estate setting overview and primary legendarium corpus. | R15: https://www.tolkienestate.com/writing/ | S15: Seeded
A16: ENT-0015 | B16: Orcs | C16: SRC-026 | D16: Tolkien's Legendarium | E16: Legendarium (literary corpus) | F16: Corrupted or bred people | G16: PPL-106 | H16: =IFERROR(VLOOKUP(G16,'Master Taxonomy'!$A$2:$B$1656,2,FALSE),"") | K16: Hostile speaking peoples associated with the powers of Morgoth and Sauron. | L16: Corruption, breeding, domination, and disputed textual origins. | M16: Their ultimate origin varies across Tolkien's developing conceptions. | N16: Foundational but ethically contested model for fantasy orcs. | O16: Primary canon | P16: Official reference reviewed | Q16: Tolkien Estate setting overview and primary legendarium corpus. | R16: https://www.tolkienestate.com/writing/ | S16: Seeded
A17: ENT-0016 | B17: Trolls | C17: SRC-026 | D17: Tolkien's Legendarium | E17: Legendarium (literary corpus) | F17: Created or corrupted beings | G17: PPL-110 | H17: =IFERROR(VLOOKUP(G17,'Master Taxonomy'!$A$2:$B$1656,2,FALSE),"") | K17: Large hostile beings appearing in several forms and periods. | L17: Corruptive making, imitation, and physical might. | M17: Different troll kinds have different intelligence and vulnerabilities. | N17: Influential giant-brute and troll archetype. | O17: Primary canon | P17: Official reference reviewed | Q17: Tolkien Estate setting overview and primary legendarium corpus. | R17: https://www.tolkienestate.com/writing/ | S17: Seeded
A18: ENT-0017 | B18: Balrogs | C18: SRC-026 | D18: Tolkien's Legendarium | E18: Legendarium (literary corpus) | F18: Fallen primordial spirits | G18: PPL-504 | H18: =IFERROR(VLOOKUP(G18,'Master Taxonomy'!$A$2:$B$1656,2,FALSE),"") | I18: PPL-501 | J18: Demons | K18: Corrupted Maiar of fire and shadow serving Morgoth. | L18: Spiritual nature, corruption, terror, and elemental manifestation. | M18: Not a biological demon species or generic fire monster. | N18: Major fallen-angelic demon and ancient lieutenant archetype. | O18: Primary canon | P18: Official reference reviewed | Q18: Tolkien Estate setting overview and primary legendarium corpus. | R18: https://www.tolkienestate.com/writing/ | S18: Seeded
A19: ENT-0018 | B19: Dragons | C19: SRC-026 | D19: Tolkien's Legendarium | E19: Legendarium (literary corpus) | F19: Created monster-kind | G19: PPL-801 | H19: =IFERROR(VLOOKUP(G19,'Master Taxonomy'!$A$2:$B$1656,2,FALSE),"") | K19: Powerful intelligent draconic beings first bred by Morgoth, including winged and wingless forms. | L19: Created monstrous lineage, cunning, physical power, and often speech. | M19: The corpus distinguishes individuals and forms rather than a game taxonomy of colors. | N19: Central Western literary dragon lineage. | O19: Primary canon | P19: Official reference reviewed | Q19: Tolkien Estate setting overview and primary legendarium corpus. | R19: https://www.tolkienestate.com/writing/ | S19: Seeded
A20: ENT-0019 | B20: Great Eagles | C20: SRC-026 | D20: Tolkien's Legendarium | E20: Legendarium (literary corpus) | F20: Sapient great beasts | G20: PPL-820 | H20: =IFERROR(VLOOKUP(G20,'Master Taxonomy'!$A$2:$B$1656,2,FALSE),"") | K20: Enormous intelligent eagles associated with Manwë and decisive interventions. | L20: Natural or spiritually elevated beasthood and divine association. | M20: They are agents with their own limits, not a routine transport mechanism. | N20: Divine messenger and rescue-beast analogue. | O20: Primary canon | P20: Official reference reviewed | Q20: Tolkien Estate setting overview and primary legendarium corpus. | R20: https://www.tolkienestate.com/writing/ | S20: Seeded
A21: ENT-0020 | B21: Great Spiders | C21: SRC-026 | D21: Tolkien's Legendarium | E21: Legendarium (literary corpus) | F21: Monstrous lineage | G21: PPL-818 | H21: =IFERROR(VLOOKUP(G21,'Master Taxonomy'!$A$2:$B$1656,2,FALSE),"") | K21: Predatory giant spiders descending from or echoing Ungoliant's monstrous lineage. | L21: Monstrous descent, appetite, poison, webs, and dark ecology. | M21: Ungoliant's own ontology remains exceptional and obscure. | N21: Foundational giant-spider and devouring-darkness archetype. | O21: Primary canon | P21: Official reference reviewed | Q21: Tolkien Estate setting overview and primary legendarium corpus. | R21: https://www.tolkienestate.com/writing/ | S21: Seeded
A22: ENT-0021 | B22: Nazgûl (Ringwraiths) | C22: SRC-026 | D22: Tolkien's Legendarium | E22: Legendarium (literary corpus) | F22: Transformed undead-like servants | G22: PPL-606 | H22: =IFERROR(VLOOKUP(G22,'Master Taxonomy'!$A$2:$B$1656,2,FALSE),"") | I22: STA-402 | J22: Relic Bearer | K22: Human kings and lords reduced to spectral servitude through Rings of Power. | L22: Artifact-mediated corruption, prolonged life, domination, and disembodiment. | M22: They are neither generic ghosts nor self-directed undead. | N22: Primary cursed-relic wraith and dark-lieutenant model. | O22: Primary canon | P22: Official reference reviewed | Q22: Tolkien Estate setting overview and primary legendarium corpus. | R22: https://www.tolkienestate.com/writing/ | S22: Seeded
A23: ENT-0022 | B23: Barrow-wights | C23: SRC-026 | D23: Tolkien's Legendarium | E23: Legendarium (literary corpus) | F23: Malignant undead spirits | G23: PPL-606 | H23: =IFERROR(VLOOKUP(G23,'Master Taxonomy'!$A$2:$B$1656,2,FALSE),"") | K23: Hostile spirits inhabiting ancient burial places and remains. | L23: Necromantic occupation of tombs and corpse-associated haunting. | M23: Distinct from the Nazgûl despite the shared English term 'wight.' | N23: Barrow-dead and tomb guardian undead analogue. | O23: Primary canon | P23: Official reference reviewed | Q23: Tolkien Estate setting overview and primary legendarium corpus. | R23: https://www.tolkienestate.com/writing/ | S23: Seeded
A24: ENT-0023 | B24: Beornings and skin-changers | C24: SRC-026 | D24: Tolkien's Legendarium | E24: Legendarium (literary corpus) | F24: Human lineage / shapeshifters | G24: PPL-1001 | H24: =IFERROR(VLOOKUP(G24,'Master Taxonomy'!$A$2:$B$1656,2,FALSE),"") | I24: ROL-511 | J24: Shapeshifting Warden | K24: Human-associated people or lineage linked to voluntary bear transformation and wilderness guardianship. | L24: Innate or inherited shapeshifting. | M24: Not presented as a conventional contagious were-creature curse. | N24: Positive guardian-shapeshifter and werebear analogue. | O24: Primary canon | P24: Official reference reviewed | Q24: Tolkien Estate setting overview and primary legendarium corpus. | R24: https://www.tolkienestate.com/writing/ | S24: Seeded
A25: ENT-0024 | B25: Rangers of the North | C25: SRC-026 | D25: Tolkien's Legendarium | E25: Legendarium (literary corpus) | F25: Martial vocation and remnant institution | G25: ROL-125 | H25: =IFERROR(VLOOKUP(G25,'Master Taxonomy'!$A$2:$B$1656,2,FALSE),"") | I25: INS-220 | J25: Adventuring Company | K25: Dúnedain guardians operating in dispersed secrecy across the former northern kingdom. | L25: Training, lineage, fieldcraft, and inherited political duty. | M25: Ranger is a historical vocation here, not a spellcasting class. | N25: Influential wilderness guardian and hidden-heir support archetype. | O25: Primary canon | P25: Official reference reviewed | Q25: Tolkien Estate setting overview and primary legendarium corpus. | R25: https://www.tolkienestate.com/writing/ | S25: Seeded
A26: ENT-0025 | B26: Rohirrim | C26: SRC-026 | D26: Tolkien's Legendarium | E26: Legendarium (literary corpus) | F26: Human culture and military tradition | G26: ROL-116 | H26: =IFERROR(VLOOKUP(G26,'Master Taxonomy'!$A$2:$B$1656,2,FALSE),"") | I26: CIV-205 | J26: Nomadic Horse Culture | K26: A settled human kingdom whose identity and warfare center strongly on horses and mounted retinues. | L26: Culture, horsemanship, fealty, and military organization. | M26: They are not strictly nomadic; the horse-culture tag is comparative, not exact. | N26: Mounted heroic culture and cavalry kingdom analogue. | O26: Primary canon | P26: Official reference reviewed | Q26: Tolkien Estate setting overview and primary legendarium corpus. | R26: https://www.tolkienestate.com/writing/ | S26: Seeded
